Traceback (most recent call last):
  File "/root/test_server/main.py", line 3, in <module>
    from plugins.session import routes as session_routes
  File "/root/test_server/plugins/session.py", line 8, in <module>
    from plugins.ftp import authorizer, get_file_size, add_new_worker
  File "/root/test_server/plugins/ftp.py", line 5, in <module>
    from pyftpdlib.handlers import FTPHandler
  File "/usr/local/lib/python3.10/site-packages/pyftpdlib/handlers.py", line 49, in <module>
    from .ioloop import _ERRNOS_DISCONNECTED
  File "<frozen importlib._bootstrap>", line 1027, in _find_and_load
  File "<frozen importlib._bootstrap>", line 1006, in _find_and_load_unlocked
  File "<frozen importlib._bootstrap>", line 688, in _load_unlocked
  File "<frozen importlib._bootstrap_external>", line 879, in exec_module
  File "<frozen importlib._bootstrap_external>", line 1012, in get_code
  File "<frozen importlib._bootstrap_external>", line 672, in _compile_bytecode
KeyboardInterrupt
[I 2023-05-09 19:32:49] concurrency model: async
[I 2023-05-09 19:32:49] masquerade (NAT) address: None
[I 2023-05-09 19:32:49] passive ports: None
[I 2023-05-09 19:32:49] >>> starting FTP server on 45.8.230.39:8889, pid=565090 <<<
[I 2023-05-09 19:47:37] 181.214.242.56:56529-[] FTP session opened (connect)
[I 2023-05-09 19:47:37] 181.214.242.56:56529-[] FTP session closed (disconnect).
[I 2023-05-09 20:15:21] 188.134.89.232:49830-[] FTP session opened (connect)
[I 2023-05-09 20:15:25] 188.134.89.232:49830-[admin] USER 'admin' logged in.
[I 2023-05-09 20:15:27] 188.134.89.232:49830-[admin] CWD /root/test_server/files 250
[I 2023-05-09 20:15:31] 188.134.89.232:49830-[admin] CWD /root/test_server/files/admin 250
[I 2023-05-09 20:15:33] 188.134.89.232:49830-[admin] CWD /root/test_server/files/architector 250
[I 2023-05-09 20:18:01] 188.134.89.232:49830-[admin] MKD /root/test_server/files/architector/БАС16-1,5-12,7х16,2-282-Гуречкин 257
[I 2023-05-09 20:18:02] 188.134.89.232:49830-[admin] CWD /root/test_server/files/architector/БАС16-1,5-12,7х16,2-282-Гуречкин 250
[I 2023-05-09 20:18:27] 188.134.89.232:50456-[] FTP session opened (connect)
[I 2023-05-09 20:18:27] 188.134.89.232:50456-[admin] USER 'admin' logged in.
[I 2023-05-09 20:18:27] 188.134.89.232:50456-[admin] CWD /root/test_server/files/architector/БАС16-1,5-12,7х16,2-282-Гуречкин 250
[I 2023-05-09 20:18:30] 188.134.89.232:50456-[admin] STOR /root/test_server/files/architector/БАС16-1,5-12,7х16,2-282-Гуречкин/3.jpg completed=1 bytes=195960 seconds=2.378
[I 2023-05-09 20:18:32] 188.134.89.232:50456-[admin] STOR /root/test_server/files/architector/БАС16-1,5-12,7х16,2-282-Гуречкин/abra_rz01.jpg completed=1 bytes=100737 seconds=0.059
[I 2023-05-09 20:19:02] 188.134.89.232:49830-[admin] CWD /root/test_server/files/architector 250
[I 2023-05-09 20:19:02] 188.134.89.232:49830-[admin] MKD /root/test_server/files/architector/БАС17-1-11,3х13-135-Власенко 257
[I 2023-05-09 20:19:08] 188.134.89.232:49830-[admin] CWD /root/test_server/files/test 250
[I 2023-05-09 20:19:10] 188.134.89.232:49830-[admin] CWD /root/test_server/files/test/era12-3-10x10-120-Test 250
[I 2023-05-09 20:19:12] 188.134.89.232:49830-[admin] CWD /root/test_server/files/architector/БАС17-1-11,3х13-135-Власенко 250
[I 2023-05-09 20:19:23] 188.134.89.232:50456-[admin] CWD /root/test_server/files/architector/БАС17-1-11,3х13-135-Власенко 250
[I 2023-05-09 20:19:24] 188.134.89.232:50456-[admin] STOR /root/test_server/files/architector/БАС17-1-11,3х13-135-Власенко/3.jpg completed=1 bytes=269181 seconds=1.074
[I 2023-05-09 20:19:26] 188.134.89.232:50456-[admin] STOR /root/test_server/files/architector/БАС17-1-11,3х13-135-Власенко/agos_rz01.jpg completed=1 bytes=96215 seconds=0.467
[I 2023-05-09 20:20:26] 188.134.89.232:50456-[admin] FTP session closed (disconnect).
[I 2023-05-09 20:22:21] 188.134.89.232:49830-[admin] CWD /root/test_server/files/architector/mba12-1.5-10x12-145-Соломонов 250
[I 2023-05-09 20:22:54] 188.134.89.232:49830-[admin] CWD /root/test_server/files/architector 250
[I 2023-05-09 20:22:54] 188.134.89.232:49830-[admin] MKD /root/test_server/files/architector/БАС03-2-9,6х9-173-Барышников 257
[I 2023-05-09 20:25:52] 188.134.89.232:49830-[admin] CWD /root/test_server/files/architector/БАС03-2-9,6х9-173-Барышников 250
[I 2023-05-09 20:26:22] 188.134.89.232:52085-[] FTP session opened (connect)
[I 2023-05-09 20:26:22] 188.134.89.232:52085-[admin] USER 'admin' logged in.
[I 2023-05-09 20:26:22] 188.134.89.232:52085-[admin] CWD /root/test_server/files/architector/БАС03-2-9,6х9-173-Барышников 250
[I 2023-05-09 20:26:22] 188.134.89.232:52085-[admin] STOR /root/test_server/files/architector/БАС03-2-9,6х9-173-Барышников /3.jpg completed=1 bytes=155073 seconds=0.184
[I 2023-05-09 20:26:27] 188.134.89.232:52085-[admin] STOR /root/test_server/files/architector/БАС03-2-9,6х9-173-Барышников /projekt-domu-alfi-rzuty-1-2.jpg completed=1 bytes=121371 seconds=0.167
[I 2023-05-09 20:27:27] 188.134.89.232:52085-[admin] FTP session closed (disconnect).
[I 2023-05-09 20:27:55] 188.134.89.232:49830-[admin] CWD /root/test_server/files 250
[I 2023-05-09 20:27:56] 188.134.89.232:49830-[admin] CWD /root/test_server/files/architector 250
[I 2023-05-09 20:27:56] 188.134.89.232:49830-[admin] CWD /root/test_server/files/architector/БАС03-2-9,6х9-173-Барышников 250
[I 2023-05-09 20:27:56] 188.134.89.232:52407-[] FTP session opened (connect)
[I 2023-05-09 20:27:56] 188.134.89.232:52408-[] FTP session opened (connect)
[I 2023-05-09 20:27:56] 188.134.89.232:52408-[admin] USER 'admin' logged in.
[I 2023-05-09 20:27:56] 188.134.89.232:52407-[admin] USER 'admin' logged in.
[I 2023-05-09 20:27:56] 188.134.89.232:52408-[admin] CWD /root/test_server/files/architector/БАС03-2-9,6х9-173-Барышников 250
[I 2023-05-09 20:27:56] 188.134.89.232:52407-[admin] CWD /root/test_server/files/architector/БАС03-2-9,6х9-173-Барышников 250
[I 2023-05-09 20:27:56] 188.134.89.232:49830-[admin] CWD /root/test_server/files/architector 250
[I 2023-05-09 20:27:56] 188.134.89.232:49830-[admin] CWD /root/test_server/files/architector/mba12-1.5-10x12-145-Соломонов 250
[I 2023-05-09 20:27:56] 188.134.89.232:52407-[admin] CWD /root/test_server/files/architector/mba12-1.5-10x12-145-Соломонов 250
[I 2023-05-09 20:27:56] 188.134.89.232:52408-[admin] CWD /root/test_server/files/architector/mba12-1.5-10x12-145-Соломонов 250
[I 2023-05-09 20:27:56] 188.134.89.232:49830-[admin] CWD /root/test_server/files/architector 250
[I 2023-05-09 20:27:56] 188.134.89.232:49830-[admin] CWD /root/test_server/files/architector/БАС17-1-11,3х13-135-Власенко 250
[I 2023-05-09 20:27:56] 188.134.89.232:52407-[admin] RETR /root/test_server/files/architector/mba12-1.5-10x12-145-Соломонов/2023-05-04_19-15-40.png completed=1 bytes=1189 seconds=0.0
[I 2023-05-09 20:27:56] 188.134.89.232:49830-[admin] CWD /root/test_server/files/architector 250
[I 2023-05-09 20:27:56] 188.134.89.232:52407-[admin] CWD /root/test_server/files/architector/БАС17-1-11,3х13-135-Власенко 250
[I 2023-05-09 20:27:56] 188.134.89.232:52408-[admin] RETR /root/test_server/files/architector/mba12-1.5-10x12-145-Соломонов/3.png completed=1 bytes=201307 seconds=0.033
[I 2023-05-09 20:27:56] 188.134.89.232:52408-[admin] CWD /root/test_server/files/architector/БАС17-1-11,3х13-135-Власенко 250
[I 2023-05-09 20:27:56] 188.134.89.232:52407-[admin] RETR /root/test_server/files/architector/БАС17-1-11,3х13-135-Власенко/agos_rz01.jpg completed=1 bytes=96215 seconds=0.019
[I 2023-05-09 20:27:56] 188.134.89.232:52407-[admin] CWD /root/test_server/files/architector/БАС16-1,5-12,7х16,2-282-Гуречкин 250
[I 2023-05-09 20:27:56] 188.134.89.232:52408-[admin] RETR /root/test_server/files/architector/БАС17-1-11,3х13-135-Власенко/3.jpg completed=1 bytes=269181 seconds=0.047
[I 2023-05-09 20:27:56] 188.134.89.232:52407-[admin] RETR /root/test_server/files/architector/БАС16-1,5-12,7х16,2-282-Гуречкин/abra_rz01.jpg completed=1 bytes=100737 seconds=0.058
[I 2023-05-09 20:27:57] 188.134.89.232:52408-[admin] CWD /root/test_server/files/architector/БАС16-1,5-12,7х16,2-282-Гуречкин 250
[I 2023-05-09 20:27:57] 188.134.89.232:52408-[admin] RETR /root/test_server/files/architector/БАС16-1,5-12,7х16,2-282-Гуречкин/3.jpg completed=1 bytes=195960 seconds=0.071
[I 2023-05-09 20:28:56] 188.134.89.232:52407-[admin] FTP session closed (disconnect).
[I 2023-05-09 20:28:57] 188.134.89.232:52408-[admin] FTP session closed (disconnect).
[I 2023-05-09 20:32:56] 188.134.89.232:49830-[admin] Control connection timed out.
[I 2023-05-09 20:32:56] 188.134.89.232:49830-[admin] FTP session closed (disconnect).
[I 2023-05-09 20:38:02] 188.134.89.232:54835-[] FTP session opened (connect)
[I 2023-05-09 20:38:03] 188.134.89.232:54835-[admin] USER 'admin' logged in.
[I 2023-05-09 20:38:03] 188.134.89.232:54835-[admin] CWD /root/test_server/files/architector 250
[I 2023-05-09 20:38:34] 188.134.89.232:54835-[admin] FTP session closed (disconnect).
[I 2023-05-09 20:49:59] 192.241.225.18:59166-[] FTP session opened (connect)
[I 2023-05-09 20:49:59] 192.241.225.18:59166-[] FTP session closed (disconnect).
Error handling request
Traceback (most recent call last):
  File "/usr/local/lib/python3.10/site-packages/aiohttp/web_protocol.py", line 332, in data_received
    messages, upgraded, tail = self._request_parser.feed_data(data)
  File "aiohttp/_http_parser.pyx", line 551, in aiohttp._http_parser.HttpParser.feed_data
aiohttp.http_exceptions.BadStatusLine: 400, message="Bad status line 'Invalid method encountered'"
[I 2023-05-09 21:00:33] 89.248.165.91:60076-[] FTP session opened (connect)
[I 2023-05-09 21:00:35] 89.248.165.91:60076-[] FTP session closed (disconnect).
Error handling request
Traceback (most recent call last):
  File "/usr/local/lib/python3.10/site-packages/aiohttp/web_protocol.py", line 332, in data_received
    messages, upgraded, tail = self._request_parser.feed_data(data)
  File "aiohttp/_http_parser.pyx", line 551, in aiohttp._http_parser.HttpParser.feed_data
aiohttp.http_exceptions.BadStatusLine: 400, message="Bad status line 'Invalid method encountered'"
Error handling request
Traceback (most recent call last):
  File "/usr/local/lib/python3.10/site-packages/aiohttp/web_protocol.py", line 332, in data_received
    messages, upgraded, tail = self._request_parser.feed_data(data)
  File "aiohttp/_http_parser.pyx", line 551, in aiohttp._http_parser.HttpParser.feed_data
aiohttp.http_exceptions.BadStatusLine: 400, message="Bad status line 'Invalid method encountered'"
Error handling request
Traceback (most recent call last):
  File "/usr/local/lib/python3.10/site-packages/aiohttp/web_protocol.py", line 332, in data_received
    messages, upgraded, tail = self._request_parser.feed_data(data)
  File "aiohttp/_http_parser.pyx", line 551, in aiohttp._http_parser.HttpParser.feed_data
aiohttp.http_exceptions.BadStatusLine: 400, message="Bad status line 'Invalid method encountered'"
Error handling request
Traceback (most recent call last):
  File "/usr/local/lib/python3.10/site-packages/aiohttp/web_protocol.py", line 332, in data_received
    messages, upgraded, tail = self._request_parser.feed_data(data)
  File "aiohttp/_http_parser.pyx", line 551, in aiohttp._http_parser.HttpParser.feed_data
aiohttp.http_exceptions.BadStatusLine: 400, message="Bad status line 'Invalid method encountered'"
Error handling request
Traceback (most recent call last):
  File "/usr/local/lib/python3.10/site-packages/aiohttp/web_protocol.py", line 332, in data_received
    messages, upgraded, tail = self._request_parser.feed_data(data)
  File "aiohttp/_http_parser.pyx", line 551, in aiohttp._http_parser.HttpParser.feed_data
aiohttp.http_exceptions.BadStatusLine: 400, message="Bad status line 'Invalid method encountered'"
Error handling request
Traceback (most recent call last):
  File "/usr/local/lib/python3.10/site-packages/aiohttp/web_protocol.py", line 332, in data_received
    messages, upgraded, tail = self._request_parser.feed_data(data)
  File "aiohttp/_http_parser.pyx", line 551, in aiohttp._http_parser.HttpParser.feed_data
aiohttp.http_exceptions.BadStatusLine: 400, message="Bad status line 'Invalid method encountered'"
[I 2023-05-09 23:21:49] 89.248.165.58:44544-[] FTP session opened (connect)
[I 2023-05-09 23:21:51] 89.248.165.58:44544-[] FTP session closed (disconnect).
[I 2023-05-10 01:05:10] 31.43.185.32:64757-[] FTP session opened (connect)
[I 2023-05-10 01:05:10] 31.43.185.32:64757-[] FTP session closed (disconnect).
[I 2023-05-10 02:28:01] 104.152.52.191:54879-[] FTP session opened (connect)
[I 2023-05-10 02:28:01] 104.152.52.191:54879-[] FTP session closed (disconnect).
Error handling request
Traceback (most recent call last):
  File "/usr/local/lib/python3.10/site-packages/aiohttp/web_protocol.py", line 332, in data_received
    messages, upgraded, tail = self._request_parser.feed_data(data)
  File "aiohttp/_http_parser.pyx", line 551, in aiohttp._http_parser.HttpParser.feed_data
aiohttp.http_exceptions.BadStatusLine: 400, message="Bad status line 'Invalid method encountered'"
Error handling request
Traceback (most recent call last):
  File "/usr/local/lib/python3.10/site-packages/aiohttp/web_protocol.py", line 332, in data_received
    messages, upgraded, tail = self._request_parser.feed_data(data)
  File "aiohttp/_http_parser.pyx", line 551, in aiohttp._http_parser.HttpParser.feed_data
aiohttp.http_exceptions.BadHttpMessage: 400, message='Pause on PRI/Upgrade'
Error handling request
Traceback (most recent call last):
  File "/usr/local/lib/python3.10/site-packages/aiohttp/web_protocol.py", line 332, in data_received
    messages, upgraded, tail = self._request_parser.feed_data(data)
  File "aiohttp/_http_parser.pyx", line 551, in aiohttp._http_parser.HttpParser.feed_data
aiohttp.http_exceptions.BadStatusLine: 400, message="Bad status line 'Invalid method encountered'"
Error handling request
Traceback (most recent call last):
  File "/usr/local/lib/python3.10/site-packages/aiohttp/web_protocol.py", line 332, in data_received
    messages, upgraded, tail = self._request_parser.feed_data(data)
  File "aiohttp/_http_parser.pyx", line 551, in aiohttp._http_parser.HttpParser.feed_data
aiohttp.http_exceptions.BadHttpMessage: 400, message='Pause on PRI/Upgrade'
Error handling request
Traceback (most recent call last):
  File "/usr/local/lib/python3.10/site-packages/aiohttp/web_protocol.py", line 332, in data_received
    messages, upgraded, tail = self._request_parser.feed_data(data)
  File "aiohttp/_http_parser.pyx", line 551, in aiohttp._http_parser.HttpParser.feed_data
aiohttp.http_exceptions.BadStatusLine: 400, message="Bad status line 'Invalid method encountered'"
Error handling request
Traceback (most recent call last):
  File "/usr/local/lib/python3.10/site-packages/aiohttp/web_protocol.py", line 332, in data_received
    messages, upgraded, tail = self._request_parser.feed_data(data)
  File "aiohttp/_http_parser.pyx", line 551, in aiohttp._http_parser.HttpParser.feed_data
aiohttp.http_exceptions.BadStatusLine: 400, message="Bad status line 'Invalid method encountered'"
Error handling request
Traceback (most recent call last):
  File "/usr/local/lib/python3.10/site-packages/aiohttp/web_protocol.py", line 332, in data_received
    messages, upgraded, tail = self._request_parser.feed_data(data)
  File "aiohttp/_http_parser.pyx", line 551, in aiohttp._http_parser.HttpParser.feed_data
aiohttp.http_exceptions.BadStatusLine: 400, message="Bad status line 'Invalid method encountered'"
Error handling request
Traceback (most recent call last):
  File "/usr/local/lib/python3.10/site-packages/aiohttp/web_protocol.py", line 332, in data_received
    messages, upgraded, tail = self._request_parser.feed_data(data)
  File "aiohttp/_http_parser.pyx", line 551, in aiohttp._http_parser.HttpParser.feed_data
aiohttp.http_exceptions.BadStatusLine: 400, message="Bad status line 'Invalid method encountered'"
Error handling request
Traceback (most recent call last):
  File "/usr/local/lib/python3.10/site-packages/aiohttp/web_protocol.py", line 332, in data_received
    messages, upgraded, tail = self._request_parser.feed_data(data)
  File "aiohttp/_http_parser.pyx", line 551, in aiohttp._http_parser.HttpParser.feed_data
aiohttp.http_exceptions.BadStatusLine: 400, message="Bad status line 'Invalid method encountered'"
Error handling request
Traceback (most recent call last):
  File "/usr/local/lib/python3.10/site-packages/aiohttp/web_protocol.py", line 332, in data_received
    messages, upgraded, tail = self._request_parser.feed_data(data)
  File "aiohttp/_http_parser.pyx", line 551, in aiohttp._http_parser.HttpParser.feed_data
aiohttp.http_exceptions.BadStatusLine: 400, message="Bad status line 'Invalid method encountered'"
Error handling request
Traceback (most recent call last):
  File "/usr/local/lib/python3.10/site-packages/aiohttp/web_protocol.py", line 332, in data_received
    messages, upgraded, tail = self._request_parser.feed_data(data)
  File "aiohttp/_http_parser.pyx", line 551, in aiohttp._http_parser.HttpParser.feed_data
aiohttp.http_exceptions.BadStatusLine: 400, message="Bad status line 'Invalid method encountered'"
Error handling request
Traceback (most recent call last):
  File "/usr/local/lib/python3.10/site-packages/aiohttp/web_protocol.py", line 332, in data_received
    messages, upgraded, tail = self._request_parser.feed_data(data)
  File "aiohttp/_http_parser.pyx", line 551, in aiohttp._http_parser.HttpParser.feed_data
aiohttp.http_exceptions.BadStatusLine: 400, message="Bad status line 'Invalid method encountered'"
[I 2023-05-10 10:21:18] 199.19.74.88:37894-[] FTP session opened (connect)
[I 2023-05-10 10:21:18] 199.19.74.88:37894-[] FTP session closed (disconnect).
Error handling request
Traceback (most recent call last):
  File "/usr/local/lib/python3.10/site-packages/aiohttp/web_protocol.py", line 332, in data_received
    messages, upgraded, tail = self._request_parser.feed_data(data)
  File "aiohttp/_http_parser.pyx", line 551, in aiohttp._http_parser.HttpParser.feed_data
aiohttp.http_exceptions.BadStatusLine: 400, message="Bad status line 'Invalid method encountered'"
Error handling request
Traceback (most recent call last):
  File "/usr/local/lib/python3.10/site-packages/aiohttp/web_protocol.py", line 332, in data_received
    messages, upgraded, tail = self._request_parser.feed_data(data)
  File "aiohttp/_http_parser.pyx", line 551, in aiohttp._http_parser.HttpParser.feed_data
aiohttp.http_exceptions.BadStatusLine: 400, message="Bad status line 'Invalid method encountered'"
Error handling request
Traceback (most recent call last):
  File "/usr/local/lib/python3.10/site-packages/aiohttp/web_protocol.py", line 332, in data_received
    messages, upgraded, tail = self._request_parser.feed_data(data)
  File "aiohttp/_http_parser.pyx", line 551, in aiohttp._http_parser.HttpParser.feed_data
aiohttp.http_exceptions.BadStatusLine: 400, message="Bad status line 'Invalid method encountered'"
[I 2023-05-10 12:41:47] 92.255.85.152:63971-[] FTP session opened (connect)
[I 2023-05-10 12:42:04] 92.255.85.152:63971-[] FTP session closed (disconnect).
Error handling request
Traceback (most recent call last):
  File "/usr/local/lib/python3.10/site-packages/aiohttp/web_protocol.py", line 332, in data_received
    messages, upgraded, tail = self._request_parser.feed_data(data)
  File "aiohttp/_http_parser.pyx", line 551, in aiohttp._http_parser.HttpParser.feed_data
aiohttp.http_exceptions.BadStatusLine: 400, message="Bad status line 'Invalid method encountered'"
Error handling request
Traceback (most recent call last):
  File "/usr/local/lib/python3.10/site-packages/aiohttp/web_protocol.py", line 332, in data_received
    messages, upgraded, tail = self._request_parser.feed_data(data)
  File "aiohttp/_http_parser.pyx", line 551, in aiohttp._http_parser.HttpParser.feed_data
aiohttp.http_exceptions.BadStatusLine: 400, message="Bad status line 'Invalid method encountered'"
Error handling request
Traceback (most recent call last):
  File "/usr/local/lib/python3.10/site-packages/aiohttp/web_protocol.py", line 332, in data_received
    messages, upgraded, tail = self._request_parser.feed_data(data)
  File "aiohttp/_http_parser.pyx", line 551, in aiohttp._http_parser.HttpParser.feed_data
aiohttp.http_exceptions.BadStatusLine: 400, message="Bad status line 'Invalid method encountered'"
[I 2023-05-10 15:16:19] 31.222.238.208:51558-[] FTP session opened (connect)
[I 2023-05-10 15:16:19] 31.222.238.208:51558-[] FTP session closed (disconnect).
[I 2023-05-10 15:18:51] 31.222.238.208:54976-[] FTP session opened (connect)
[I 2023-05-10 15:18:51] 31.222.238.208:54976-[] FTP session closed (disconnect).
[I 2023-05-10 15:29:55] 92.255.85.152:64125-[] FTP session opened (connect)
[I 2023-05-10 15:30:22] 92.255.85.152:64125-[] FTP session closed (disconnect).
Error handling request
Traceback (most recent call last):
  File "/usr/local/lib/python3.10/site-packages/aiohttp/web_protocol.py", line 433, in _handle_request
    resp = await request_handler(request)
  File "/usr/local/lib/python3.10/site-packages/aiohttp/web_app.py", line 504, in _handle
    resp = await handler(request)
  File "/root/test_server/plugins/static.py", line 15, in styles_handler
    data = await get.get_css(url.split('/')[-1])
  File "/root/test_server/plugins/html.py", line 38, in get_css
    async with aiopen(join(self._path, 'styles', css_filename), 'r', encoding='utf-8') as file:
  File "/usr/local/lib/python3.10/site-packages/aiofiles/base.py", line 78, in __aenter__
    self._obj = await self._coro
  File "/usr/local/lib/python3.10/site-packages/aiofiles/threadpool/__init__.py", line 80, in _open
    f = yield from loop.run_in_executor(executor, cb)
  File "/usr/local/lib/python3.10/concurrent/futures/thread.py", line 52, in run
    result = self.fn(*self.args, **self.kwargs)
FileNotFoundError: [Errno 2] No such file or directory: 'html/styles/style.css'
Error handling request
Traceback (most recent call last):
  File "/usr/local/lib/python3.10/site-packages/aiohttp/web_protocol.py", line 433, in _handle_request
    resp = await request_handler(request)
  File "/usr/local/lib/python3.10/site-packages/aiohttp/web_app.py", line 504, in _handle
    resp = await handler(request)
  File "/root/test_server/plugins/static.py", line 13, in styles_handler
    data = await get.get_sass(url.split('/')[-1])
  File "/root/test_server/plugins/html.py", line 45, in get_sass
    async with aiopen(join(self._path, 'styles', scss_filename), 'r', encoding='utf-8') as file:
  File "/usr/local/lib/python3.10/site-packages/aiofiles/base.py", line 78, in __aenter__
    self._obj = await self._coro
  File "/usr/local/lib/python3.10/site-packages/aiofiles/threadpool/__init__.py", line 80, in _open
    f = yield from loop.run_in_executor(executor, cb)
  File "/usr/local/lib/python3.10/concurrent/futures/thread.py", line 52, in run
    result = self.fn(*self.args, **self.kwargs)
FileNotFoundError: [Errno 2] No such file or directory: 'html/styles/style.scss'
Error handling request
Traceback (most recent call last):
  File "/usr/local/lib/python3.10/site-packages/aiohttp/web_protocol.py", line 433, in _handle_request
    resp = await request_handler(request)
  File "/usr/local/lib/python3.10/site-packages/aiohttp/web_app.py", line 504, in _handle
    resp = await handler(request)
  File "/root/test_server/plugins/static.py", line 21, in script_handler
    data = await get.get_js(str(request.url).split('/')[-1])
  File "/root/test_server/plugins/html.py", line 52, in get_js
    async with aiopen(join(self._path, 'scripts', js_filename), 'r', encoding='utf-8') as file:
  File "/usr/local/lib/python3.10/site-packages/aiofiles/base.py", line 78, in __aenter__
    self._obj = await self._coro
  File "/usr/local/lib/python3.10/site-packages/aiofiles/threadpool/__init__.py", line 80, in _open
    f = yield from loop.run_in_executor(executor, cb)
  File "/usr/local/lib/python3.10/concurrent/futures/thread.py", line 52, in run
    result = self.fn(*self.args, **self.kwargs)
FileNotFoundError: [Errno 2] No such file or directory: 'html/scripts/pass.js'
Error handling request
Traceback (most recent call last):
  File "/usr/local/lib/python3.10/site-packages/aiohttp/web_protocol.py", line 433, in _handle_request
    resp = await request_handler(request)
  File "/usr/local/lib/python3.10/site-packages/aiohttp/web_app.py", line 504, in _handle
    resp = await handler(request)
  File "/root/test_server/plugins/static.py", line 15, in styles_handler
    data = await get.get_css(url.split('/')[-1])
  File "/root/test_server/plugins/html.py", line 38, in get_css
    async with aiopen(join(self._path, 'styles', css_filename), 'r', encoding='utf-8') as file:
  File "/usr/local/lib/python3.10/site-packages/aiofiles/base.py", line 78, in __aenter__
    self._obj = await self._coro
  File "/usr/local/lib/python3.10/site-packages/aiofiles/threadpool/__init__.py", line 80, in _open
    f = yield from loop.run_in_executor(executor, cb)
  File "/usr/local/lib/python3.10/concurrent/futures/thread.py", line 52, in run
    result = self.fn(*self.args, **self.kwargs)
FileNotFoundError: [Errno 2] No such file or directory: 'html/styles/style.css'
Error handling request
Traceback (most recent call last):
  File "/usr/local/lib/python3.10/site-packages/aiohttp/web_protocol.py", line 433, in _handle_request
    resp = await request_handler(request)
  File "/usr/local/lib/python3.10/site-packages/aiohttp/web_app.py", line 504, in _handle
    resp = await handler(request)
  File "/root/test_server/plugins/static.py", line 13, in styles_handler
    data = await get.get_sass(url.split('/')[-1])
  File "/root/test_server/plugins/html.py", line 45, in get_sass
    async with aiopen(join(self._path, 'styles', scss_filename), 'r', encoding='utf-8') as file:
  File "/usr/local/lib/python3.10/site-packages/aiofiles/base.py", line 78, in __aenter__
    self._obj = await self._coro
  File "/usr/local/lib/python3.10/site-packages/aiofiles/threadpool/__init__.py", line 80, in _open
    f = yield from loop.run_in_executor(executor, cb)
  File "/usr/local/lib/python3.10/concurrent/futures/thread.py", line 52, in run
    result = self.fn(*self.args, **self.kwargs)
FileNotFoundError: [Errno 2] No such file or directory: 'html/styles/style.scss'
Error handling request
Traceback (most recent call last):
  File "/usr/local/lib/python3.10/site-packages/aiohttp/web_protocol.py", line 433, in _handle_request
    resp = await request_handler(request)
  File "/usr/local/lib/python3.10/site-packages/aiohttp/web_app.py", line 504, in _handle
    resp = await handler(request)
  File "/root/test_server/plugins/static.py", line 21, in script_handler
    data = await get.get_js(str(request.url).split('/')[-1])
  File "/root/test_server/plugins/html.py", line 52, in get_js
    async with aiopen(join(self._path, 'scripts', js_filename), 'r', encoding='utf-8') as file:
  File "/usr/local/lib/python3.10/site-packages/aiofiles/base.py", line 78, in __aenter__
    self._obj = await self._coro
  File "/usr/local/lib/python3.10/site-packages/aiofiles/threadpool/__init__.py", line 80, in _open
    f = yield from loop.run_in_executor(executor, cb)
  File "/usr/local/lib/python3.10/concurrent/futures/thread.py", line 52, in run
    result = self.fn(*self.args, **self.kwargs)
FileNotFoundError: [Errno 2] No such file or directory: 'html/scripts/pass.js'
Error handling request
Traceback (most recent call last):
  File "/usr/local/lib/python3.10/site-packages/aiohttp/web_protocol.py", line 433, in _handle_request
    resp = await request_handler(request)
  File "/usr/local/lib/python3.10/site-packages/aiohttp/web_app.py", line 504, in _handle
    resp = await handler(request)
  File "/root/test_server/plugins/static.py", line 15, in styles_handler
    data = await get.get_css(url.split('/')[-1])
  File "/root/test_server/plugins/html.py", line 38, in get_css
    async with aiopen(join(self._path, 'styles', css_filename), 'r', encoding='utf-8') as file:
  File "/usr/local/lib/python3.10/site-packages/aiofiles/base.py", line 78, in __aenter__
    self._obj = await self._coro
  File "/usr/local/lib/python3.10/site-packages/aiofiles/threadpool/__init__.py", line 80, in _open
    f = yield from loop.run_in_executor(executor, cb)
  File "/usr/local/lib/python3.10/concurrent/futures/thread.py", line 52, in run
    result = self.fn(*self.args, **self.kwargs)
FileNotFoundError: [Errno 2] No such file or directory: 'html/styles/style.css'
Error handling request
Traceback (most recent call last):
  File "/usr/local/lib/python3.10/site-packages/aiohttp/web_protocol.py", line 433, in _handle_request
    resp = await request_handler(request)
  File "/usr/local/lib/python3.10/site-packages/aiohttp/web_app.py", line 504, in _handle
    resp = await handler(request)
  File "/root/test_server/plugins/static.py", line 13, in styles_handler
    data = await get.get_sass(url.split('/')[-1])
  File "/root/test_server/plugins/html.py", line 45, in get_sass
    async with aiopen(join(self._path, 'styles', scss_filename), 'r', encoding='utf-8') as file:
  File "/usr/local/lib/python3.10/site-packages/aiofiles/base.py", line 78, in __aenter__
    self._obj = await self._coro
  File "/usr/local/lib/python3.10/site-packages/aiofiles/threadpool/__init__.py", line 80, in _open
    f = yield from loop.run_in_executor(executor, cb)
  File "/usr/local/lib/python3.10/concurrent/futures/thread.py", line 52, in run
    result = self.fn(*self.args, **self.kwargs)
FileNotFoundError: [Errno 2] No such file or directory: 'html/styles/style.scss'
Error handling request
Traceback (most recent call last):
  File "/usr/local/lib/python3.10/site-packages/aiohttp/web_protocol.py", line 433, in _handle_request
    resp = await request_handler(request)
  File "/usr/local/lib/python3.10/site-packages/aiohttp/web_app.py", line 504, in _handle
    resp = await handler(request)
  File "/root/test_server/plugins/static.py", line 21, in script_handler
    data = await get.get_js(str(request.url).split('/')[-1])
  File "/root/test_server/plugins/html.py", line 52, in get_js
    async with aiopen(join(self._path, 'scripts', js_filename), 'r', encoding='utf-8') as file:
  File "/usr/local/lib/python3.10/site-packages/aiofiles/base.py", line 78, in __aenter__
    self._obj = await self._coro
  File "/usr/local/lib/python3.10/site-packages/aiofiles/threadpool/__init__.py", line 80, in _open
    f = yield from loop.run_in_executor(executor, cb)
  File "/usr/local/lib/python3.10/concurrent/futures/thread.py", line 52, in run
    result = self.fn(*self.args, **self.kwargs)
FileNotFoundError: [Errno 2] No such file or directory: 'html/scripts/pass.js'
Error handling request
Traceback (most recent call last):
  File "/usr/local/lib/python3.10/site-packages/aiohttp/web_protocol.py", line 433, in _handle_request
    resp = await request_handler(request)
  File "/usr/local/lib/python3.10/site-packages/aiohttp/web_app.py", line 504, in _handle
    resp = await handler(request)
  File "/root/test_server/plugins/static.py", line 15, in styles_handler
    data = await get.get_css(url.split('/')[-1])
  File "/root/test_server/plugins/html.py", line 38, in get_css
    async with aiopen(join(self._path, 'styles', css_filename), 'r', encoding='utf-8') as file:
  File "/usr/local/lib/python3.10/site-packages/aiofiles/base.py", line 78, in __aenter__
    self._obj = await self._coro
  File "/usr/local/lib/python3.10/site-packages/aiofiles/threadpool/__init__.py", line 80, in _open
    f = yield from loop.run_in_executor(executor, cb)
  File "/usr/local/lib/python3.10/concurrent/futures/thread.py", line 52, in run
    result = self.fn(*self.args, **self.kwargs)
FileNotFoundError: [Errno 2] No such file or directory: 'html/styles/style.css'
Error handling request
Traceback (most recent call last):
  File "/usr/local/lib/python3.10/site-packages/aiohttp/web_protocol.py", line 433, in _handle_request
    resp = await request_handler(request)
  File "/usr/local/lib/python3.10/site-packages/aiohttp/web_app.py", line 504, in _handle
    resp = await handler(request)
  File "/root/test_server/plugins/static.py", line 13, in styles_handler
    data = await get.get_sass(url.split('/')[-1])
  File "/root/test_server/plugins/html.py", line 45, in get_sass
    async with aiopen(join(self._path, 'styles', scss_filename), 'r', encoding='utf-8') as file:
  File "/usr/local/lib/python3.10/site-packages/aiofiles/base.py", line 78, in __aenter__
    self._obj = await self._coro
  File "/usr/local/lib/python3.10/site-packages/aiofiles/threadpool/__init__.py", line 80, in _open
    f = yield from loop.run_in_executor(executor, cb)
  File "/usr/local/lib/python3.10/concurrent/futures/thread.py", line 52, in run
    result = self.fn(*self.args, **self.kwargs)
FileNotFoundError: [Errno 2] No such file or directory: 'html/styles/style.scss'
Error handling request
Traceback (most recent call last):
  File "/usr/local/lib/python3.10/site-packages/aiohttp/web_protocol.py", line 433, in _handle_request
    resp = await request_handler(request)
  File "/usr/local/lib/python3.10/site-packages/aiohttp/web_app.py", line 504, in _handle
    resp = await handler(request)
  File "/root/test_server/plugins/session.py", line 214, in api_page
    return json_response(data={'response': await page.get_two_picture(data['data']['path'])})
  File "/root/test_server/plugins/html.py", line 103, in get_two_picture
    files = listdir('files/'+path)
FileNotFoundError: [Errno 2] No such file or directory: 'files//architector/БАС03-2-9,6х9-173-Барышников'
Error handling request
Traceback (most recent call last):
  File "/usr/local/lib/python3.10/site-packages/aiohttp/web_protocol.py", line 433, in _handle_request
    resp = await request_handler(request)
  File "/usr/local/lib/python3.10/site-packages/aiohttp/web_app.py", line 504, in _handle
    resp = await handler(request)
  File "/root/test_server/plugins/session.py", line 214, in api_page
    return json_response(data={'response': await page.get_two_picture(data['data']['path'])})
  File "/root/test_server/plugins/html.py", line 103, in get_two_picture
    files = listdir('files/'+path)
FileNotFoundError: [Errno 2] No such file or directory: 'files//architector/БАС03-2-9,6х9-173-Барышников'
